Workbook

Sheet Dashboard
A1: INVENTORY & SUPPLY CHAIN DASHBOARD
A3: Synthetic inventory dataset | Currency: INR
A4: Warehouse Filter | B4: All | D4: Choose a warehouse to update KPI cards.
A6: TOTAL INVENTORY VALUE | D6: TOTAL UNITS IN STOCK | G6: REORDER ITEMS | J6: AVERAGE STOCK COVER
A7: =IF($B$4="All",SUM(Clean_Data!$N$2:$N$421),SUMIFS(Clean_Data!$N$2:$N$421,Clean_Data!$D$2:$D$421,$B$4)) | D7: =IF($B$4="All",SUM(Clean_Data!$H$2:$H$421),SUMIFS(Clean_Data!$H$2:$H$421,Clean_Data!$D$2:$D$421,$B$4)) | G7: =IF($B$4="All",COUNTIF(Clean_Data!$R$2:$R$421,"Reorder Now"),COUNTIFS(Clean_Data!$D$2:$D$421,$B$4,Clean_Data!$R$2:$R$421,"Reorder Now")) | J7: =IFERROR(IF($B$4="All",AVERAGE(Clean_Data!$Q$2:$Q$421),AVERAGEIF(Clean_Data!$D$2:$D$421,$B$4,Clean_Data!$Q$2:$Q$421)),0)
A42: KPI cards respond to warehouse selector; charts show full dataset summaries.

Sheet Raw_Data
A1: SKU | B1: Product | C1: Category | D1: Warehouse | E1: Supplier | F1: Unit_Cost_INR | G1: Selling_Price_INR | H1: Stock_On_Hand | I1: Units_Sold_30D | J1: Reorder_Point | K1: Target_Stock | L1: Lead_Time_Days | M1: Units_Received_30D
A2: SKU-0001 | B2: Standing Desk | C2: Furniture | D2: Mumbai | E2: Global Gadgets | F2: 18500 | G2: 14300 | H2: 55 | I2: 6 | J2: 15 | K2: 45 | L2: 7 | M2: 60
A3: SKU-0002 | B3: Standing Desk | C3: Furniture | D3: Delhi | E3: TechNova Distributors | F3: 18500 | G3: 14300 | H3: 96 | I3: 45 | J3: 20 | K3: 45 | L3: 18 | M3: 33
A4: SKU-0003 | B4: Mechanical Keyboard | C4: Accessories | D4: Mumbai | E4: Prime Office Supply | F4: 2800 | G4: 1650 | H4: 144 | I4: 60 | J4: 70 | K4: 250 | L4: 7 | M4: 7
A5: SKU-0004 | B5: Power Bank | C5: Accessories | D5: Mumbai | E5: Global Gadgets | F5: 1600 | G5: 900 | H5: 406 | I5: 15 | J5: 70 | K5: 240 | L5: 10 | M5: 0
A6: SKU-0005 | B6: Standing Desk | C6: Furniture | D6: Hyderabad | E6: TechNova Distributors | F6: 18500 | G6: 14300 | H6: 2 | I6: 21 | J6: 15 | K6: 45 | L6: 2 | M6: 30
A7: SKU-0006 | B7: Webcam HD | C7: Electronics | D7: Mumbai | E7: Prime Office Supply | F7: 3200 | G7: 2150 | H7: 74 | I7: 31 | J7: 45 | K7: 150 | L7: 18 | M7: 63
A8: SKU-0007 | B8: Mechanical Keyboard | C8: Accessories | D8: Mumbai | E8: Urban Workspace | F8: 2800 | G8: 1650 | H8: 241 | I8: 33 | J8: 75 | K8: 250 | L8: 11 | M8: 59
A9: SKU-0008 | B9: Wireless Mouse | C9: Accessories | D9: Delhi | E9: Prime Office Supply | F9: 850 | G9: 420 | H9: 217 | I9: 40 | J9: 120 | K9: 500 | L9: 7 | M9: 63
A10: SKU-0009 | B10: 27-inch Monitor | C10: Electronics | D10: Hyderabad | E10: Apex Electronics | F10: 14500 | G10: 11200 | H10: 46 | I10: 62 | J10: 40 | K10: 100 | L10: 9 | M10: 50
A11: SKU-0010 | B11: Power Bank | C11: Accessories | D11: Delhi | E11: Urban Workspace | F11: 1600 | G11: 900 | H11: 476 | I11: 11 | J11: 70 | K11: 240 | L11: 7 | M11: 50
A12: SKU-0011 | B12: Webcam HD | C12: Electronics | D12: Hyderabad | E12: Urban Workspace | F12: 3200 | G12: 2150 | H12: 103 | I12: 51 | J12: 50 | K12: 150 | L12: 6 | M12: 63
A13: SKU-0012 | B13: Printer | C13: Electronics | D13: Pune | E13: Urban Workspace | F13: 9800 | G13: 7600 | H13: 13 | I13: 8 | J13: 25 | K13: 70 | L13: 4 | M13: 46
... A34: SKU-0033 | B34: Standing Desk | C34: Furniture | D34: Mumbai | E34: Apex Electronics | F34: 18500 | G34: 14300 | H34: 91 | I34: 59 | J34: 15 | K34: 45 | L34: 11 | M34: 9
A35: SKU-0034 | B35: 27-inch Monitor | C35: Electronics | D35: Mumbai | F35: 14500 | G35: 11200 | H35: 48 | I35: 72 | J35: 35 | K35: 100 | L35: 6 | M35: 12
A36: SKU-0035 | B36: Mechanical Keyboard | C36: Accessories | D36: Pune | E36: TechNova Distributors | F36: 2800 | G36: 1650 | H36: 424 | I36: 65 | J36: 75 | K36: 250 | L36: 8 | M36: 58
A37: SKU-0036 | B37: Power Bank | C37: Accessories | D37: Delhi | E37: Prime Office Supply | F37: 1600 | G37: 900 | H37: 51 | I37: 32 | J37: 75 | K37: 240 | L37: 5 | M37: 47
A38: SKU-0037 | B38: Ergonomic Footrest | C38: Furniture | D38: Bengaluru | E38: Urban Workspace | F38: 2200 | G38: 1300 | H38: 240 | I38: 4 | J38: 40 | K38: 130 | L38: 8 | M38: 21
A39: SKU-0038 | B39: 27-inch Monitor | C39: Electronics | D39: Mumbai | E39: TechNova Distributors | F39: 14500 | G39: 11200 | H39: 41 | I39: 67 | J39: 40 | K39: 100 | L39: 4 | M39: 21
A40: SKU-0039 | B40: Ergonomic Footrest | C40: Furniture | D40: Hyderabad | E40: Prime Office Supply | F40: 2200 | G40: 1300 | H40: 246 | I40: 38 | J40: 40 | K40: 130 | L40: 15 | M40: 38
A41: SKU-0040 | B41: Ergonomic Footrest | C41: Furniture | D41: Bengaluru | E41: Prime Office Supply | F41: 2200 | G41: 1300 | H41: 155 | I41: 73 | J41: 45 | K41: 130 | L41: 10 | M41: 60
A42: SKU-0041 | B42: Laptop Stand | C42: Accessories | D42: Delhi | E42: Global Gadgets | F42: 1350 | G42: 700 | H42: 289 | I42: 70 | J42: 95 | K42: 300 | L42: 6 | M42: 34
A43: SKU-0042 | B43: Desk Lamp | C43: Furniture | D43: Hyderabad | E43: TechNova Distributors | F43: 1150 | G43: 620 | H43: 265 | I43: 30 | J43: 60 | K43: 200 | L43: 12 | M43: 60
A44: SKU-0043 | B44: Ergonomic Footrest | C44: Furniture | D44: Hyderabad | E44: TechNova Distributors | F44: 2200 | G44: 1300 | H44: 159 | I44: 57 | J44: 40 | K44: 130 | L44: 4 | M44: 41
A45: SKU-0044 | B45: USB-C Hub | C45: Accessories | D45: Bengaluru | E45: Apex Electronics | F45: 1900 | G45: 1050 | H45: 245 | I45: 72 | J45: 65 | K45: 220 | L45: 2 | M45: 25
A46: SKU-0045 | B46: Desk Lamp | C46: Furniture | D46: Bengaluru | E46: TechNova Distributors | F46: 1150 | G46: 620 | H46: 249 | I46: 37 | J46: 60 | K46: 200 | L46: 12 | M46: 52
A47: SKU-0046 | B47: Office Chair | C47: Furniture | D47: Hyderabad | E47: Prime Office Supply | F47: 7800 | G47: 5600 | H47: 53 | I47: 13 | J47: 25 | K47: 80 | L47: 17 | M47: 8
... A207: SKU-0206 | B207: Office Chair | C207: Furniture | D207: Pune | E207: TechNova Distributors | F207: 7800 | G207: 5600 | H207: 48 | I207: 60 | J207: 30 | K207: 80 | L207: 16 | M207: 74
A208: SKU-0207 | B208: Standing Desk | C208: Furniture | D208: Delhi | F208: 18500 | G208: 14300 | H208: 11 | I208: 59 | J208: 15 | K208: 45 | L208: 13 | M208: 58
A209: SKU-0208 | B209: Ethernet Adapter | C209: Accessories | D209: Pune | E209: Urban Workspace | F209: 750 | G209: 330 | H209: 337 | I209: 67 | J209: 80 | K209: 280 | L209: 11 | M209: 18
A210: SKU-0209 | B210: USB-C Hub | C210: Accessories | D210: Pune | E210: Apex Electronics | F210: 1900 | G210: 1050 | H210: 34 | I210: 21 | J210: 65 | K210: 220 | L210: 10 | M210: 79
A211: SKU-0210 | B211: Desk Lamp | C211: Furniture | D211: Bengaluru | E211: TechNova Distributors | F211: 1150 | G211: 620 | H211: 41 | I211: 26 | J211: 60 | K211: 200 | L211: 16 | M211: 59
A212: SKU-0211 | B212: Desk Lamp | C212: Furniture | D212: Mumbai | E212: Prime Office Supply | F212: 1150 | G212: 620 | H212: 51 | I212: 17 | J212: 65 | K212: 200 | L212: 17 | M212: 29
A213: SKU-0212 | B213: Desk Lamp | C213: Furniture | D213: Bengaluru | E213: Apex Electronics | F213: 1150 | G213: 620 | H213: 19 | I213: 13 | J213: 60 | K213: 200 | L213: 3 | M213: 58
A214: SKU-0213 | B214: USB-C Hub | C214: Accessories | D214: Hyderabad | E214: Urban Workspace | F214: 1900 | G214: 1050 | H214: 261 | I214: 22 | J214: 70 | K214: 220 | L214: 13 | M214: 32
A215: SKU-0214 | B215: Printer | C215: Electronics | D215: Mumbai | E215: Apex Electronics | F215: 9800 | G215: 7600 | H215: 120 | I215: 16 | J215: 20 | K215: 70 | L215: 17 | M215: 52
A216: SKU-0215 | B216: Wireless Mouse | C216: Accessories | D216: Pune | E216: Global Gadgets | F216: 850 | G216: 420 | H216: 612 | I216: 42 | J216: 120 | K216: 500 | L216: 14 | M216: 43
A217: SKU-0216 | B217: Desk Lamp | C217: Furniture | D217: Hyderabad | E217: Prime Office Supply | F217: 1150 | G217: 620 | H217: 214 | I217: 36 | J217: 60 | K217: 200 | L217: 12 | M217: 64
A218: SKU-0217 | B218: Power Bank | C218: Accessories | D218: Pune | E218: TechNova Distributors | F218: 1600 | G218: 900 | H218: 107 | I218: 19 | J218: 70 | K218: 240 | L218: 3 | M218: 45
A219: SKU-0218 | B219: Webcam HD | C219: Electronics | D219: Delhi | E219: Prime Office Supply | F219: 3200 | G219: 2150 | H219: 153 | I219: 62 | J219: 50 | K219: 150 | L219: 18 | M219: 14
...

Sheet Clean_Data
A1: SKU | B1: Product | C1: Category | D1: Warehouse | E1: Supplier | F1: Unit_Cost_INR | G1: Selling_Price_INR | H1: Stock_On_Hand | I1: Units_Sold_30D | J1: Reorder_Point | K1: Target_Stock | L1: Lead_Time_Days | M1: Units_Received_30D | N1: Inventory_Value_INR | O1: Potential_Revenue_INR | P1: Gross_Profit_Per_Unit_INR | Q1: Stock_Cover_Days | R1: Stock_Status | S1: Reorder_Qty
A2: SKU-0001 | B2: Standing Desk | C2: Furniture | D2: Mumbai | E2: Global Gadgets | F2: 18500 | G2: 14300 | H2: 55 | I2: 6 | J2: 15 | K2: 45 | L2: 7 | M2: 60 | N2: 1017500 | O2: 786500 | P2: -4200 | Q2: 275 | R2: Healthy | S2: 0
A3: SKU-0002 | B3: Standing Desk | C3: Furniture | D3: Delhi | E3: TechNova Distributors | F3: 18500 | G3: 14300 | H3: 96 | I3: 45 | J3: 20 | K3: 45 | L3: 18 | M3: 33 | N3: 1776000 | O3: 1372800 | P3: -4200 | Q3: 64 | R3: Overstock | S3: 0
A4: SKU-0003 | B4: Mechanical Keyboard | C4: Accessories | D4: Mumbai | E4: Prime Office Supply | F4: 2800 | G4: 1650 | H4: 144 | I4: 60 | J4: 70 | K4: 250 | L4: 7 | M4: 7 | N4: 403200 | O4: 237600 | P4: -1150 | Q4: 72 | R4: Healthy | S4: 0
A5: SKU-0004 | B5: Power Bank | C5: Accessories | D5: Mumbai | E5: Global Gadgets | F5: 1600 | G5: 900 | H5: 406 | I5: 15 | J5: 70 | K5: 240 | L5: 10 | M5: 0 | N5: 649600 | O5: 365400 | P5: -700 | Q5: 812 | R5: Overstock | S5: 0
A6: SKU-0005 | B6: Standing Desk | C6: Furniture | D6: Hyderabad | E6: TechNova Distributors | F6: 18500 | G6: 14300 | H6: 2 | I6: 21 | J6: 15 | K6: 45 | L6: 2 | M6: 30 | N6: 37000 | O6: 28600 | P6: -4200 | Q6: 2.9 | R6: Reorder Now | S6: 43
A7: SKU-0006 | B7: Webcam HD | C7: Electronics | D7: Mumbai | E7: Prime Office Supply | F7: 3200 | G7: 2150 | H7: 74 | I7: 31 | J7: 45 | K7: 150 | L7: 18 | M7: 63 | N7: 236800 | O7: 159100 | P7: -1050 | Q7: 71.6 | R7: Healthy | S7: 0
A8: SKU-0007 | B8: Mechanical Keyboard | C8: Accessories | D8: Mumbai | E8: Urban Workspace | F8: 2800 | G8: 1650 | H8: 241 | I8: 33 | J8: 75 | K8: 250 | L8: 11 | M8: 59 | N8: 674800 | O8: 397650 | P8: -1150 | Q8: 219.1 | R8: Healthy | S8: 0
A9: SKU-0008 | B9: Wireless Mouse | C9: Accessories | D9: Delhi | E9: Prime Office Supply | F9: 850 | G9: 420 | H9: 217 | I9: 40 | J9: 120 | K9: 500 | L9: 7 | M9: 63 | N9: 184450 | O9: 91140 | P9: -430 | Q9: 162.8 | R9: Healthy | S9: 0
A10: SKU-0009 | B10: 27-inch Monitor | C10: Electronics | D10: Hyderabad | E10: Apex Electronics | F10: 14500 | G10: 11200 | H10: 46 | I10: 62 | J10: 40 | K10: 100 | L10: 9 | M10: 50 | N10: 667000 | O10: 515200 | P10: -3300 | Q10: 22.3 | R10: Healthy | S10: 0
A11: SKU-0010 | B11: Power Bank | C11: Accessories | D11: Delhi | E11: Urban Workspace | F11: 1600 | G11: 900 | H11: 476 | I11: 11 | J11: 70 | K11: 240 | L11: 7 | M11: 50 | N11: 761600 | O11: 428400 | P11: -700 | Q11: 1298.2 | R11: Overstock | S11: 0
A12: SKU-0011 | B12: Webcam HD | C12: Electronics | D12: Hyderabad | E12: Urban Workspace | F12: 3200 | G12: 2150 | H12: 103 | I12: 51 | J12: 50 | K12: 150 | L12: 6 | M12: 63 | N12: 329600 | O12: 221450 | P12: -1050 | Q12: 60.6 | R12: Healthy | S12: 0
A13: SKU-0012 | B13: Printer | C13: Electronics | D13: Pune | E13: Urban Workspace | F13: 9800 | G13: 7600 | H13: 13 | I13: 8 | J13: 25 | K13: 70 | L13: 4 | M13: 46 | N13: 127400 | O13: 98800 | P13: -2200 | Q13: 48.8 | R13: Reorder Now | S13: 57
... A24: SKU-0023 | B24: Mechanical Keyboard | C24: Accessories | D24: Bengaluru | E24: Urban Workspace | F24: 2800 | G24: 1650 | H24: 456 | I24: 49 | J24: 70 | K24: 250 | L24: 17 | M24: 72 | N24: 1276800 | O24: 752400 | P24: -1150 | Q24: 279.2 | R24: Overstock | S24: 0
A25: SKU-0024 | B25: Bluetooth Headphones | C25: Electronics | D25: Bengaluru | E25: Global Gadgets | F25: 4200 | G25: 2750 | H25: 141 | I25: 0 | J25: 60 | K25: 180 | L25: 13 | M25: 63 | N25: 592200 | O25: 387750 | P25: -1450 | R25: Healthy | S25: 0
A26: SKU-0025 | B26: USB-C Hub | C26: Accessories | D26: Delhi | E26: TechNova Distributors | F26: 1900 | G26: 1050 | H26: 322 | I26: 44 | J26: 65 | K26: 220 | L26: 9 | M26: 2 | N26: 611800 | O26: 338100 | P26: -850 | Q26: 219.5 | R26: Healthy | S26: 0
A27: SKU-0026 | B27: 27-inch Monitor | C27: Electronics | D27: Bengaluru | E27: Global Gadgets | F27: 14500 | G27: 11200 | H27: 16 | I27: 12 | J27: 40 | K27: 100 | L27: 18 | M27: 44 | N27: 232000 | O27: 179200 | P27: -3300 | Q27: 40 | R27: Reorder Now | S27: 84
A28: SKU-0027 | B28: Webcam HD | C28: Electronics | D28: Delhi | E28: Global Gadgets | F28: 3200 | G28: 2150 | H28: 146 | I28: 1 | J28: 45 | K28: 150 | L28: 5 | M28: 13 | N28: 467200 | O28: 313900 | P28: -1050 | Q28: 4380 | R28: Healthy | S28: 0
A29: SKU-0028 | B29: Standing Desk | C29: Furniture | D29: Mumbai | E29: Apex Electronics | F29: 18500 | G29: 14300 | H29: 5 | I29: 5 | J29: 20 | K29: 45 | L29: 3 | M29: 64 | N29: 92500 | O29: 71500 | P29: -4200 | Q29: 30 | R29: Reorder Now | S29: 40
A30: SKU-0029 | B30: Printer | C30: Electronics | D30: Pune | E30: Prime Office Supply | F30: 9800 | G30: 7600 | H30: 62 | I30: 51 | J30: 25 | K30: 70 | L30: 11 | M30: 57 | N30: 607600 | O30: 471200 | P30: -2200 | Q30: 36.5 | R30: Healthy | S30: 0
A31: SKU-0030 | B31: External SSD 1TB | C31: Electronics | D31: Mumbai | E31: Prime Office Supply | F31: 7200 | G31: 5400 | H31: 107 | I31: 24 | J31: 30 | K31: 100 | L31: 17 | M31: 56 | N31: 770400 | O31: 577800 | P31: -1800 | Q31: 133.8 | R31: Healthy | S31: 0
A32: SKU-0031 | B32: External SSD 1TB | C32: Electronics | D32: Mumbai | E32: Prime Office Supply | F32: 7200 | G32: 5400 | H32: 37 | I32: 63 | J32: 30 | K32: 100 | L32: 14 | M32: 32 | N32: 266400 | O32: 199800 | P32: -1800 | Q32: 17.6 | R32: Healthy | S32: 0
A33: SKU-0032 | B33: 27-inch Monitor | C33: Electronics | D33: Mumbai | E33: Urban Workspace | F33: 14500 | G33: 11200 | H33: 22 | I33: 8 | J33: 35 | K33: 100 | L33: 2 | M33: 56 | N33: 319000 | O33: 246400 | P33: -3300 | Q33: 82.5 | R33: Reorder Now | S33: 78
A34: SKU-0033 | B34: Standing Desk | C34: Furniture | D34: Mumbai | E34: Apex Electronics | F34: 18500 | G34: 14300 | H34: 91 | I34: 59 | J34: 15 | K34: 45 | L34: 11 | M34: 9 | N34: 1683500 | O34: 1301300 | P34: -4200 | Q34: 46.3 | R34: Overstock | S34: 0
A35: SKU-0034 | B35: 27-inch Monitor | C35: Electronics | D35: Mumbai | E35: Not specified | F35: 14500 | G35: 11200 | H35: 48 | I35: 72 | J35: 35 | K35: 100 | L35: 6 | M35: 12 | N35: 696000 | O35: 537600 | P35: -3300 | Q35: 20 | R35: Healthy | S35: 0
A36: SKU-0035 | B36: Mechanical Keyboard | C36: Accessories | D36: Pune | E36: TechNova Distributors | F36: 2800 | G36: 1650 | H36: 424 | I36: 65 | J36: 75 | K36: 250 | L36: 8 | M36: 58 | N36: 1187200 | O36: 699600 | P36: -1150 | Q36: 195.7 | R36: Overstock | S36: 0
A37: SKU-0036 | B37: Power Bank | C37: Accessories | D37: Delhi | E37: Prime Office Supply | F37: 1600 | G37: 900 | H37: 51 | I37: 32 | J37: 75 | K37: 240 | L37: 5 | M37: 47 | N37: 81600 | O37: 45900 | P37: -700 | Q37: 47.8 | R37: Reorder Now | S37: 189
... A158: SKU-0157 | B158: Printer | C158: Electronics | D158: Mumbai | E158: Global Gadgets | F158: 9800 | G158: 7600 | H158: 129 | I158: 43 | J158: 20 | K158: 70 | L158: 17 | M158: 35 | N158: 1264200 | O158: 980400 | P158: -2200 | Q158: 90 | R158: Overstock | S158: 0
A159: SKU-0158 | B159: Laptop Stand | C159: Accessories | D159: Pune | E159: Urban Workspace | F159: 1350 | G159: 700 | H159: 163 | I159: 0 | J159: 95 | K159: 300 | L159: 12 | M159: 58 | N159: 220050 | O159: 114100 | P159: -650 | R159: Healthy | S159: 0
A160: SKU-0159 | B160: Ergonomic Footrest | C160: Furniture | D160: Hyderabad | E160: Apex Electronics | F160: 2200 | G160: 1300 | H160: 228 | I160: 71 | J160: 40 | K160: 130 | L160: 18 | M160: 55 | N160: 501600 | O160: 296400 | P160: -900 | Q160: 96.3 | R160: Overstock | S160: 0
A161: SKU-0160 | B161: Standing Desk | C161: Furniture | D161: Hyderabad | E161: Prime Office Supply | F161: 18500 | G161: 14300 | H161: 4 | I161: 58 | J161: 15 | K161: 45 | L161: 7 | M161: 70 | N161: 74000 | O161: 57200 | P161: -4200 | Q161: 2.1 | R161: Reorder Now | S161: 41
A162: SKU-0161 | B162: Ethernet Adapter | C162: Accessories | D162: Delhi | E162: Apex Electronics | F162: 750 | G162: 330 | H162: 174 | I162: 41 | J162: 80 | K162: 280 | L162: 15 | M162: 37 | N162: 130500 | O162: 57420 | P162: -420 | Q162: 127.3 | R162: Healthy | S162: 0
A163: SKU-0162 | B163: Office Chair | C163: Furniture | D163: Mumbai | E163: Apex Electronics | F163: 7800 | G163: 5600 | H163: 39 | I163: 26 | J163: 25 | K163: 80 | L163: 12 | M163: 21 | N163: 304200 | O163: 218400 | P163: -2200 | Q163: 45 | R163: Healthy | S163: 0
A164: SKU-0163 | B164: 27-inch Monitor | C164: Electronics | D164: Bengaluru | E164: Apex Electronics | F164: 14500 | G164: 11200 | H164: 26 | I164: 31 | J164: 40 | K164: 100 | L164: 12 | M164: 31 | N164: 377000 | O164: 291200 | P164: -3300 | Q164: 25.2 | R164: Reorder Now | S164: 74
A165: SKU-0164 | B165: Desk Lamp | C165: Furniture | D165: Pune | E165: Prime Office Supply | F165: 1150 | G165: 620 | H165: 22 | I165: 46 | J165: 65 | K165: 200 | L165: 3 | M165: 23 | N165: 25300 | O165: 13640 | P165: -530 | Q165: 14.3 | R165: Reorder Now | S165: 178
A166: SKU-0165 | B166: USB-C Hub | C166: Accessories | D166: Pune | E166: TechNova Distributors | F166: 1900 | G166: 1050 | H166: 34 | I166: 8 | J166: 65 | K166: 220 | L166: 14 | M166: 40 | N166: 64600 | O166: 35700 | P166: -850 | Q166: 127.5 | R166: Reorder Now | S166: 186
A167: SKU-0166 | B167: Wireless Mouse | C167: Accessories | D167: Pune | E167: TechNova Distributors | F167: 850 | G167: 420 | H167: 69 | I167: 35 | J167: 120 | K167: 500 | L167: 9 | M167: 72 | N167: 58650 | O167: 28980 | P167: -430 | Q167: 59.1 | R167: Reorder Now | S167: 431
A168: SKU-0167 | B168: 27-inch Monitor | C168: Electronics | D168: Delhi | E168: Global Gadgets | F168: 14500 | G168: 11200 | H168: 144 | I168: 63 | J168: 35 | K168: 100 | L168: 12 | M168: 1 | N168: 2088000 | O168: 1612800 | P168: -3300 | Q168: 68.6 | R168: Healthy | S168: 0
A169: SKU-0168 | B169: USB-C Hub | C169: Accessories | D169: Bengaluru | E169: TechNova Distributors | F169: 1900 | G169: 1050 | H169: 106 | I169: 65 | J169: 65 | K169: 220 | L169: 5 | M169: 11 | N169: 201400 | O169: 111300 | P169: -850 | Q169: 48.9 | R169: Healthy | S169: 0
A170: SKU-0169 | B170: Standing Desk | C170: Furniture | D170: Hyderabad | E170: Prime Office Supply | F170: 18500 | G170: 14300 | H170: 26 | I170: 56 | J170: 15 | K170: 45 | L170: 8 | M170: 37 | N170: 481000 | O170: 371800 | P170: -4200 | Q170: 13.9 | R170: Healthy | S170: 0
...

Sheet Analysis
A1: INVENTORY ANALYTICS | SUMMARY TABLES
A3: Category | B3: Inventory Value (INR) | C3: Units in Stock | D3: Units Sold (30D) | E3: Reorder Items | G3: Warehouse | H3: Inventory Value (INR)
A4: Accessories | B4: =SUMIFS(Clean_Data!$N$2:$N$421,Clean_Data!$C$2:$C$421,A4) | C4: =SUMIFS(Clean_Data!$H$2:$H$421,Clean_Data!$C$2:$C$421,A4) | D4: =SUMIFS(Clean_Data!$I$2:$I$421,Clean_Data!$C$2:$C$421,A4) | E4: =COUNTIFS(Clean_Data!$C$2:$C$421,A4,Clean_Data!$R$2:$R$421,"Reorder Now") | G4: Delhi | H4: =SUMIFS(Clean_Data!$N$2:$N$421,Clean_Data!$D$2:$D$421,G4)
A5: Electronics | B5: =SUMIFS(Clean_Data!$N$2:$N$421,Clean_Data!$C$2:$C$421,A5) | C5: =SUMIFS(Clean_Data!$H$2:$H$421,Clean_Data!$C$2:$C$421,A5) | D5: =SUMIFS(Clean_Data!$I$2:$I$421,Clean_Data!$C$2:$C$421,A5) | E5: =COUNTIFS(Clean_Data!$C$2:$C$421,A5,Clean_Data!$R$2:$R$421,"Reorder Now") | G5: Bengaluru | H5: =SUMIFS(Clean_Data!$N$2:$N$421,Clean_Data!$D$2:$D$421,G5)
A6: Furniture | B6: =SUMIFS(Clean_Data!$N$2:$N$421,Clean_Data!$C$2:$C$421,A6) | C6: =SUMIFS(Clean_Data!$H$2:$H$421,Clean_Data!$C$2:$C$421,A6) | D6: =SUMIFS(Clean_Data!$I$2:$I$421,Clean_Data!$C$2:$C$421,A6) | E6: =COUNTIFS(Clean_Data!$C$2:$C$421,A6,Clean_Data!$R$2:$R$421,"Reorder Now") | G6: Mumbai | H6: =SUMIFS(Clean_Data!$N$2:$N$421,Clean_Data!$D$2:$D$421,G6)
G7: Pune | H7: =SUMIFS(Clean_Data!$N$2:$N$421,Clean_Data!$D$2:$D$421,G7)
G8: Hyderabad | H8: =SUMIFS(Clean_Data!$N$2:$N$421,Clean_Data!$D$2:$D$421,G8)
A10: Stock Status | B10: SKU Count
A11: Reorder Now | B11: =COUNTIF(Clean_Data!$R$2:$R$421,A11)
A12: Healthy | B12: =COUNTIF(Clean_Data!$R$2:$R$421,A12)
A13: Overstock | B13: =COUNTIF(Clean_Data!$R$2:$R$421,A13)

Sheet Data_Dictionary
A1: Column | B1: Description | C1: Format
A2: SKU | B2: Unique synthetic inventory record identifier | C2: Text
A3: Product | B3: Product name | C3: Text
A4: Category | B4: Product category | C4: Category
A5: Warehouse | B5: Warehouse location | C5: City
A6: Supplier | B6: Supplier name | C6: Text
A7: Unit_Cost_INR | B7: Purchase cost per unit | C7: INR
A8: Selling_Price_INR | B8: Selling price per unit | C8: INR
A9: Stock_On_Hand | B9: Current units in stock | C9: Units
A10: Units_Sold_30D | B10: Units sold in the last 30 days | C10: Units
A11: Reorder_Point | B11: Stock threshold that triggers reorder review | C11: Units
A12: Target_Stock | B12: Desired stock quantity | C12: Units
... A20: Reorder_Qty | B20: Target stock minus on-hand stock when reorder threshold is met | C20: Units

Sheet Start_Here
A1: PROJECT GUIDE | INVENTORY ANALYTICS
A4: Objective | B4: Analyze synthetic inventory records to estimate stock value, identify reorder candidates, and compare warehouse/category stock.
A5: Dashboard | B5: Change Dashboard!B4 to All or a warehouse to update KPI cards.
A6: Raw_Data | B6: Original synthetic inventory records preserved.
A7: Clean_Data | B7: Missing suppliers labeled Not specified; text fields trimmed; inventory value, stock cover, status, and reorder quantity added.
A8: Analysis | B8: Formula-driven category, warehouse, and stock-status summaries.
A9: Stock status | B9: Reorder Now if on-hand stock <= reorder point; Overstock if stock > 1.5 × target; otherwise Healthy.
A10: Important | B10: Synthetic practice data. Reorder labels are rule-based and should be validated against real demand, lead time, and safety stock.
